Workbook

Sheet Auto Sales data - Copy
A1: ORDER_NUMBER | B1: QUANTITY_ORDERED | C1: PRICE_EACH | D1: ORDER_LINE_NUMBER | E1: SALES | F1: ORDER_DATE | G1: STATUS | H1: PRODUCT_LINE | I1: MSRP | J1: PRODUCT_CODE | K1: CUSTOMER_NAME | L1: PHONE | M1: ADDRESS_LINE_1 | N1: CITY | O1: POSTAL_CODE | P1: COUNTRY | Q1: CONTACT_LAST_NAME | R1: CONTACT_FIRST_NAME | S1: DEAL_SIZE | T1: DAYS_SINCE_LAST_ORDER | U1: Total_Orders_Per_Customer | V1: Total_Sales_Per_Customer | W1: R-Score(1-5) | X1: F-Score(1-5) | Y1: M-Score(1-5) | Z1: RFM Code | AA1: Segment Name | AB1: Strategy | AF1: CUSTOMER_NAME | AG1: TOTAL ORDERS | AH1: TOTAL SALES
A2: 10153 | B2: 20 | C2: 245.2 | D2: 11 | E2: 4904 | F2: 43371 | G2: Shipped | H2: Classic Cars | I2: 207 | J2: S12_1108 | K2: Euro Shopping Channel | L2: (91) 555 94 44 | M2: C/ Moralzarzal, 86 | N2: Madrid | O2: 28034 | P2: Spain | Q2: Freyre | R2: Diego | S2: Medium | T2: 790 | U2: =VLOOKUP(Auto_Sales_data___Copy[[#This Row],[CUSTOMER_NAME]],$AF$2:$AH$90,2,FALSE) -> 259 | V2: =VLOOKUP(Auto_Sales_data___Copy[[#This Row],[CUSTOMER_NAME]],$AF$2:$AH$90,3,FALSE) -> 912294.11 | W2: =6-MATCH(Auto_Sales_data___Copy[[#This Row],[DAYS_SINCE_LAST_ORDER]],Table2[R-Cutoff],1) -> 5 | X2: =MATCH(Auto_Sales_data___Copy[[#This Row],[Total_Orders_Per_Customer]],Table2[F-Cutoff],1) -> 5 | Y2: =MATCH(Auto_Sales_data___Copy[[#This Row],[Total_Sales_Per_Customer]],Table2[M-Cutoff],1) -> 5 | Z2: =Auto_Sales_data___Copy[[#This Row],[R-Score(1-5)]]&Auto_Sales_data___Copy[[#This Row],[F-Score(1-5)]]&Auto_Sales_data___Copy[[#This Row],[M-Score(1-5)]] -> 555 | AA2: {=_xlfn.IFS(OR(Auto_Sales_data___Copy[[#This Row],[R-Score(1-5)]]=5,Auto_Sales_data___Copy[[#This Row],[R-Score(1-5)]]=4)*AND(Auto_Sales_data___Copy[[#This Row],[F-Score(1-5)]]>=4,Auto_Sales_data___Copy[[#This Row],[M-Score(1-5)]]>=4),'Segments & Strategies'!$A$2,AND(Auto_Sales_data___Copy[[#This Row],[R-Score(1-5)]]=3,Auto_Sales_data___Copy[[#This Row],[F-Score(1-5)]]>=4,Auto_Sales_data___Copy[[#This Row],[M-Score(1-5)]]>=4),'Segments & Strategies'!$A$3,AND(Auto_Sales_data___Copy[[#This Row],[R-Score(1-5)]]>=4,Auto_Sales_data___Copy[[#This Row],[F-Score(1-5)]]=5,Auto_Sales_data___Copy[[#This Row],[M-Score(1-5)]]<=3),'Segments & Strategies'!$A$4, AND(Auto_Sales_data___Copy[[#This Row],[R-Score(1-5)]]=2,Auto_Sales_data___Copy[[#This Row],[F-Score(1-5)]]>=4,Auto_Sales_data___Copy[[#This Row],[M-Score(1-5)]]>=4),'Segments & Strategies'!$A$6,AND(Auto_Sales_data___Copy[[#This Row],[R-Score(1-5)]]=1,Auto_Sales_data___Copy[[#This Row],[F-Score(1-5)]]<=2,Auto_Sales_data___Copy[[#This Row],[M-Score(1-5)]]<=2),'Segments & Strategies'!$A$8,AND(Auto_Sales_data___Copy[[#This Row],[R-Score(1-5)]]<=3,Auto_Sales_data___Copy[[#This Row],[F-Score(1-5)]]<=3,Auto_Sales_data___Copy[[#This Row],[M-Score(1-5)]]<=2), 'Segments & Strategies'!$A$7, TRUE,'Segments & Strategies'!$A$5)} -> Champion | AB2: =VLOOKUP(Auto_Sales_data___Copy[[#This Row],[Segment Name]],Table3[],2,FALSE) -> VIP Recognitioon & Inclusivity | AF2: Euro Shopping Channel | AG2: 259 | AH2: 912294.11
A3: 10153 | B3: 42 | C3: 128.42 | D3: 12 | E3: 5393.64 | F3: 43371 | G3: Shipped | H3: Classic Cars | I3: 151 | J3: S12_3148 | K3: Euro Shopping Channel | L3: (91) 555 94 44 | M3: C/ Moralzarzal, 86 | N3: Madrid | O3: 28034 | P3: Spain | Q3: Freyre | R3: Diego | S3: Medium | T3: 866 | U3: =VLOOKUP(Auto_Sales_data___Copy[[#This Row],[CUSTOMER_NAME]],$AF$2:$AH$90,2,FALSE) -> 259 | V3: =VLOOKUP(Auto_Sales_data___Copy[[#This Row],[CUSTOMER_NAME]],$AF$2:$AH$90,3,FALSE) -> 912294.11 | W3: =6-MATCH(Auto_Sales_data___Copy[[#This Row],[DAYS_SINCE_LAST_ORDER]],Table2[R-Cutoff],1) -> 5 | X3: =MATCH(Auto_Sales_data___Copy[[#This Row],[Total_Orders_Per_Customer]],Table2[F-Cutoff],1) -> 5 | Y3: =MATCH(Auto_Sales_data___Copy[[#This Row],[Total_Sales_Per_Customer]],Table2[M-Cutoff],1) -> 5 | Z3: =Auto_Sales_data___Copy[[#This Row],[R-Score(1-5)]]&Auto_Sales_data___Copy[[#This Row],[F-Score(1-5)]]&Auto_Sales_data___Copy[[#This Row],[M-Score(1-5)]] -> 555 | AA3: {=_xlfn.IFS(OR(Auto_Sales_data___Copy[[#This Row],[R-Score(1-5)]]=5,Auto_Sales_data___Copy[[#This Row],[R-Score(1-5)]]=4)*AND(Auto_Sales_data___Copy[[#This Row],[F-Score(1-5)]]>=4,Auto_Sales_data___Copy[[#This Row],[M-Score(1-5)]]>=4),'Segments & Strategies'!$A$2,AND(Auto_Sales_data___Copy[[#This Row],[R-Score(1-5)]]=3,Auto_Sales_data___Copy[[#This Row],[F-Score(1-5)]]>=4,Auto_Sales_data___Copy[[#This Row],[M-Score(1-5)]]>=4),'Segments & Strategies'!$A$3,AND(Auto_Sales_data___Copy[[#This Row],[R-Score(1-5)]]>=4,Auto_Sales_data___Copy[[#This Row],[F-Score(1-5)]]=5,Auto_Sales_data___Copy[[#This Row],[M-Score(1-5)]]<=3),'Segments & Strategies'!$A$4, AND(Auto_Sales_data___Copy[[#This Row],[R-Score(1-5)]]=2,Auto_Sales_data___Copy[[#This Row],[F-Score(1-5)]]>=4,Auto_Sales_data___Copy[[#This Row],[M-Score(1-5)]]>=4),'Segments & Strategies'!$A$6,AND(Auto_Sales_data___Copy[[#This Row],[R-Score(1-5)]]=1,Auto_Sales_data___Copy[[#This Row],[F-Score(1-5)]]<=2,Auto_Sales_data___Copy[[#This Row],[M-Score(1-5)]]<=2),'Segments & Strategies'!$A$8,AND(Auto_Sales_data___Copy[[#This Row],[R-Score(1-5)]]<=3,Auto_Sales_data___Copy[[#This Row],[F-Score(1-5)]]<=3,Auto_Sales_data___Copy[[#This Row],[M-Score(1-5)]]<=2), 'Segments & Strategies'!$A$7, TRUE,'Segments & Strategies'!$A$5)} -> Champion | AB3: =VLOOKUP(Auto_Sales_data___Copy[[#This Row],[Segment Name]],Table3[],2,FALSE) -> VIP Recognitioon & Inclusivity | AF3: Mini Gifts Distributors Ltd. | AG3: 180 | AH3: 654858.06
A4: 10153 | B4: 49 | C4: 143.61 | D4: 10 | E4: 7036.89 | F4: 43371 | G4: Shipped | H4: Classic Cars | I4: 173 | J4: S12_3891 | K4: Euro Shopping Channel | L4: (91) 555 94 44 | M4: C/ Moralzarzal, 86 | N4: Madrid | O4: 28034 | P4: Spain | Q4: Freyre | R4: Diego | S4: Large | T4: 915 | U4: =VLOOKUP(Auto_Sales_data___Copy[[#This Row],[CUSTOMER_NAME]],$AF$2:$AH$90,2,FALSE) -> 259 | V4: =VLOOKUP(Auto_Sales_data___Copy[[#This Row],[CUSTOMER_NAME]],$AF$2:$AH$90,3,FALSE) -> 912294.11 | W4: =6-MATCH(Auto_Sales_data___Copy[[#This Row],[DAYS_SINCE_LAST_ORDER]],Table2[R-Cutoff],1) -> 5 | X4: =MATCH(Auto_Sales_data___Copy[[#This Row],[Total_Orders_Per_Customer]],Table2[F-Cutoff],1) -> 5 | Y4: =MATCH(Auto_Sales_data___Copy[[#This Row],[Total_Sales_Per_Customer]],Table2[M-Cutoff],1) -> 5 | Z4: =Auto_Sales_data___Copy[[#This Row],[R-Score(1-5)]]&Auto_Sales_data___Copy[[#This Row],[F-Score(1-5)]]&Auto_Sales_data___Copy[[#This Row],[M-Score(1-5)]] -> 555 | AA4: {=_xlfn.IFS(OR(Auto_Sales_data___Copy[[#This Row],[R-Score(1-5)]]=5,Auto_Sales_data___Copy[[#This Row],[R-Score(1-5)]]=4)*AND(Auto_Sales_data___Copy[[#This Row],[F-Score(1-5)]]>=4,Auto_Sales_data___Copy[[#This Row],[M-Score(1-5)]]>=4),'Segments & Strategies'!$A$2,AND(Auto_Sales_data___Copy[[#This Row],[R-Score(1-5)]]=3,Auto_Sales_data___Copy[[#This Row],[F-Score(1-5)]]>=4,Auto_Sales_data___Copy[[#This Row],[M-Score(1-5)]]>=4),'Segments & Strategies'!$A$3,AND(Auto_Sales_data___Copy[[#This Row],[R-Score(1-5)]]>=4,Auto_Sales_data___Copy[[#This Row],[F-Score(1-5)]]=5,Auto_Sales_data___Copy[[#This Row],[M-Score(1-5)]]<=3),'Segments & Strategies'!$A$4, AND(Auto_Sales_data___Copy[[#This Row],[R-Score(1-5)]]=2,Auto_Sales_data___Copy[[#This Row],[F-Score(1-5)]]>=4,Auto_Sales_data___Copy[[#This Row],[M-Score(1-5)]]>=4),'Segments & Strategies'!$A$6,AND(Auto_Sales_data___Copy[[#This Row],[R-Score(1-5)]]=1,Auto_Sales_data___Copy[[#This Row],[F-Score(1-5)]]<=2,Auto_Sales_data___Copy[[#This Row],[M-Score(1-5)]]<=2),'Segments & Strategies'!$A$8,AND(Auto_Sales_data___Copy[[#This Row],[R-Score(1-5)]]<=3,Auto_Sales_data___Copy[[#This Row],[F-Score(1-5)]]<=3,Auto_Sales_data___Copy[[#This Row],[M-Score(1-5)]]<=2), 'Segments & Strategies'!$A$7, TRUE,'Segments & Strategies'!$A$5)} -> Champion | AB4: =VLOOKUP(Auto_Sales_data___Copy[[#This Row],[Segment Name]],Table3[],2,FALSE) -> VIP Recognitioon & Inclusivity | AF4: Australian Collectors, Co. | AG4: 55 | AH4: 200995.41
A5: 10203 | B5: 20 | C5: 196.52 | D5: 8 | E5: 3930.4 | F5: 43436 | G5: Shipped | H5: Classic Cars | I5: 194 | J5: S12_1099 | K5: Euro Shopping Channel | L5: (91) 555 94 44 | M5: C/ Moralzarzal, 86 | N5: Madrid | O5: 28034 | P5: Spain | Q5: Freyre | R5: Diego | S5: Medium | T5: 704 | U5: =VLOOKUP(Auto_Sales_data___Copy[[#This Row],[CUSTOMER_NAME]],$AF$2:$AH$90,2,FALSE) -> 259 | V5: =VLOOKUP(Auto_Sales_data___Copy[[#This Row],[CUSTOMER_NAME]],$AF$2:$AH$90,3,FALSE) -> 912294.11 | W5: =6-MATCH(Auto_Sales_data___Copy[[#This Row],[DAYS_SINCE_LAST_ORDER]],Table2[R-Cutoff],1) -> 5 | X5: =MATCH(Auto_Sales_data___Copy[[#This Row],[Total_Orders_Per_Customer]],Table2[F-Cutoff],1) -> 5 | Y5: =MATCH(Auto_Sales_data___Copy[[#This Row],[Total_Sales_Per_Customer]],Table2[M-Cutoff],1) -> 5 | Z5: =Auto_Sales_data___Copy[[#This Row],[R-Score(1-5)]]&Auto_Sales_data___Copy[[#This Row],[F-Score(1-5)]]&Auto_Sales_data___Copy[[#This Row],[M-Score(1-5)]] -> 555 | AA5: {=_xlfn.IFS(OR(Auto_Sales_data___Copy[[#This Row],[R-Score(1-5)]]=5,Auto_Sales_data___Copy[[#This Row],[R-Score(1-5)]]=4)*AND(Auto_Sales_data___Copy[[#This Row],[F-Score(1-5)]]>=4,Auto_Sales_data___Copy[[#This Row],[M-Score(1-5)]]>=4),'Segments & Strategies'!$A$2,AND(Auto_Sales_data___Copy[[#This Row],[R-Score(1-5)]]=3,Auto_Sales_data___Copy[[#This Row],[F-Score(1-5)]]>=4,Auto_Sales_data___Copy[[#This Row],[M-Score(1-5)]]>=4),'Segments & Strategies'!$A$3,AND(Auto_Sales_data___Copy[[#This Row],[R-Score(1-5)]]>=4,Auto_Sales_data___Copy[[#This Row],[F-Score(1-5)]]=5,Auto_Sales_data___Copy[[#This Row],[M-Score(1-5)]]<=3),'Segments & Strategies'!$A$4, AND(Auto_Sales_data___Copy[[#This Row],[R-Score(1-5)]]=2,Auto_Sales_data___Copy[[#This Row],[F-Score(1-5)]]>=4,Auto_Sales_data___Copy[[#This Row],[M-Score(1-5)]]>=4),'Segments & Strategies'!$A$6,AND(Auto_Sales_data___Copy[[#This Row],[R-Score(1-5)]]=1,Auto_Sales_data___Copy[[#This Row],[F-Score(1-5)]]<=2,Auto_Sales_data___Copy[[#This Row],[M-Score(1-5)]]<=2),'Segments & Strategies'!$A$8,AND(Auto_Sales_data___Copy[[#This Row],[R-Score(1-5)]]<=3,Auto_Sales_data___Copy[[#This Row],[F-Score(1-5)]]<=3,Auto_Sales_data___Copy[[#This Row],[M-Score(1-5)]]<=2), 'Segments & Strategies'!$A$7, TRUE,'Segments & Strategies'!$A$5)} -> Champion | AB5: =VLOOKUP(Auto_Sales_data___Copy[[#This Row],[Segment Name]],Table3[],2,FALSE) -> VIP Recognitioon & Inclusivity | AF5: Muscle Machine Inc | AG5: 48 | AH5: 197736.94
A6: 10203 | B6: 20 | C6: 112.74 | D6: 6 | E6: 2254.8 | F6: 43436 | G6: Shipped | H6: Classic Cars | I6: 117 | J6: S12_3380 | K6: Euro Shopping Channel | L6: (91) 555 94 44 | M6: C/ Moralzarzal, 86 | N6: Madrid | O6: 28034 | P6: Spain | Q6: Freyre | R6: Diego | S6: Small | T6: 829 | U6: =VLOOKUP(Auto_Sales_data___Copy[[#This Row],[CUSTOMER_NAME]],$AF$2:$AH$90,2,FALSE) -> 259 | V6: =VLOOKUP(Auto_Sales_data___Copy[[#This Row],[CUSTOMER_NAME]],$AF$2:$AH$90,3,FALSE) -> 912294.11 | W6: =6-MATCH(Auto_Sales_data___Copy[[#This Row],[DAYS_SINCE_LAST_ORDER]],Table2[R-Cutoff],1) -> 5 | X6: =MATCH(Auto_Sales_data___Copy[[#This Row],[Total_Orders_Per_Customer]],Table2[F-Cutoff],1) -> 5 | Y6: =MATCH(Auto_Sales_data___Copy[[#This Row],[Total_Sales_Per_Customer]],Table2[M-Cutoff],1) -> 5 | Z6: =Auto_Sales_data___Copy[[#This Row],[R-Score(1-5)]]&Auto_Sales_data___Copy[[#This Row],[F-Score(1-5)]]&Auto_Sales_data___Copy[[#This Row],[M-Score(1-5)]] -> 555 | AA6: {=_xlfn.IFS(OR(Auto_Sales_data___Copy[[#This Row],[R-Score(1-5)]]=5,Auto_Sales_data___Copy[[#This Row],[R-Score(1-5)]]=4)*AND(Auto_Sales_data___Copy[[#This Row],[F-Score(1-5)]]>=4,Auto_Sales_data___Copy[[#This Row],[M-Score(1-5)]]>=4),'Segments & Strategies'!$A$2,AND(Auto_Sales_data___Copy[[#This Row],[R-Score(1-5)]]=3,Auto_Sales_data___Copy[[#This Row],[F-Score(1-5)]]>=4,Auto_Sales_data___Copy[[#This Row],[M-Score(1-5)]]>=4),'Segments & Strategies'!$A$3,AND(Auto_Sales_data___Copy[[#This Row],[R-Score(1-5)]]>=4,Auto_Sales_data___Copy[[#This Row],[F-Score(1-5)]]=5,Auto_Sales_data___Copy[[#This Row],[M-Score(1-5)]]<=3),'Segments & Strategies'!$A$4, AND(Auto_Sales_data___Copy[[#This Row],[R-Score(1-5)]]=2,Auto_Sales_data___Copy[[#This Row],[F-Score(1-5)]]>=4,Auto_Sales_data___Copy[[#This Row],[M-Score(1-5)]]>=4),'Segments & Strategies'!$A$6,AND(Auto_Sales_data___Copy[[#This Row],[R-Score(1-5)]]=1,Auto_Sales_data___Copy[[#This Row],[F-Score(1-5)]]<=2,Auto_Sales_data___Copy[[#This Row],[M-Score(1-5)]]<=2),'Segments & Strategies'!$A$8,AND(Auto_Sales_data___Copy[[#This Row],[R-Score(1-5)]]<=3,Auto_Sales_data___Copy[[#This Row],[F-Score(1-5)]]<=3,Auto_Sales_data___Copy[[#This Row],[M-Score(1-5)]]<=2), 'Segments & Strategies'!$A$7, TRUE,'Segments & Strategies'!$A$5)} -> Champion | AB6: =VLOOKUP(Auto_Sales_data___Copy[[#This Row],[Segment Name]],Table3[],2,FALSE) -> VIP Recognitioon & Inclusivity | AF6: La Rochelle Gifts | AG6: 53 | AH6: 180124.9
A7: 10203 | B7: 44 | C7: 82.99 | D7: 9 | E7: 3651.56 | F7: 43436 | G7: Shipped | H7: Classic Cars | I7: 79 | J7: S12_3990 | K7: Euro Shopping Channel | L7: (91) 555 94 44 | M7: C/ Moralzarzal, 86 | N7: Madrid | O7: 28034 | P7: Spain | Q7: Freyre | R7: Diego | S7: Medium | T7: 879 | U7: =VLOOKUP(Auto_Sales_data___Copy[[#This Row],[CUSTOMER_NAME]],$AF$2:$AH$90,2,FALSE) -> 259 | V7: =VLOOKUP(Auto_Sales_data___Copy[[#This Row],[CUSTOMER_NAME]],$AF$2:$AH$90,3,FALSE) -> 912294.11 | W7: =6-MATCH(Auto_Sales_data___Copy[[#This Row],[DAYS_SINCE_LAST_ORDER]],Table2[R-Cutoff],1) -> 5 | X7: =MATCH(Auto_Sales_data___Copy[[#This Row],[Total_Orders_Per_Customer]],Table2[F-Cutoff],1) -> 5 | Y7: =MATCH(Auto_Sales_data___Copy[[#This Row],[Total_Sales_Per_Customer]],Table2[M-Cutoff],1) -> 5 | Z7: =Auto_Sales_data___Copy[[#This Row],[R-Score(1-5)]]&Auto_Sales_data___Copy[[#This Row],[F-Score(1-5)]]&Auto_Sales_data___Copy[[#This Row],[M-Score(1-5)]] -> 555 | AA7: {=_xlfn.IFS(OR(Auto_Sales_data___Copy[[#This Row],[R-Score(1-5)]]=5,Auto_Sales_data___Copy[[#This Row],[R-Score(1-5)]]=4)*AND(Auto_Sales_data___Copy[[#This Row],[F-Score(1-5)]]>=4,Auto_Sales_data___Copy[[#This Row],[M-Score(1-5)]]>=4),'Segments & Strategies'!$A$2,AND(Auto_Sales_data___Copy[[#This Row],[R-Score(1-5)]]=3,Auto_Sales_data___Copy[[#This Row],[F-Score(1-5)]]>=4,Auto_Sales_data___Copy[[#This Row],[M-Score(1-5)]]>=4),'Segments & Strategies'!$A$3,AND(Auto_Sales_data___Copy[[#This Row],[R-Score(1-5)]]>=4,Auto_Sales_data___Copy[[#This Row],[F-Score(1-5)]]=5,Auto_Sales_data___Copy[[#This Row],[M-Score(1-5)]]<=3),'Segments & Strategies'!$A$4, AND(Auto_Sales_data___Copy[[#This Row],[R-Score(1-5)]]=2,Auto_Sales_data___Copy[[#This Row],[F-Score(1-5)]]>=4,Auto_Sales_data___Copy[[#This Row],[M-Score(1-5)]]>=4),'Segments & Strategies'!$A$6,AND(Auto_Sales_data___Copy[[#This Row],[R-Score(1-5)]]=1,Auto_Sales_data___Copy[[#This Row],[F-Score(1-5)]]<=2,Auto_Sales_data___Copy[[#This Row],[M-Score(1-5)]]<=2),'Segments & Strategies'!$A$8,AND(Auto_Sales_data___Copy[[#This Row],[R-Score(1-5)]]<=3,Auto_Sales_data___Copy[[#This Row],[F-Score(1-5)]]<=3,Auto_Sales_data___Copy[[#This Row],[M-Score(1-5)]]<=2), 'Segments & Strategies'!$A$7, TRUE,'Segments & Strategies'!$A$5)} -> Champion | AB7: =VLOOKUP(Auto_Sales_data___Copy[[#This Row],[Segment Name]],Table3[],2,FALSE) -> VIP Recognitioon & Inclusivity | AF7: Dragon Souveniers, Ltd. | AG7: 43 | AH7: 172989.68
A8: 10203 | B8: 47 | C8: 110.55 | D8: 5 | E8: 5195.85 | F8: 43436 | G8: Shipped | H8: Classic Cars | I8: 115 | J8: S12_4675 | K8: Euro Shopping Channel | L8: (91) 555 94 44 | M8: C/ Moralzarzal, 86 | N8: Madrid | O8: 28034 | P8: Spain | Q8: Freyre | R8: Diego | S8: Medium | T8: 930 | U8: =VLOOKUP(Auto_Sales_data___Copy[[#This Row],[CUSTOMER_NAME]],$AF$2:$AH$90,2,FALSE) -> 259 | V8: =VLOOKUP(Auto_Sales_data___Copy[[#This Row],[CUSTOMER_NAME]],$AF$2:$AH$90,3,FALSE) -> 912294.11 | W8: =6-MATCH(Auto_Sales_data___Copy[[#This Row],[DAYS_SINCE_LAST_ORDER]],Table2[R-Cutoff],1) -> 5 | X8: =MATCH(Auto_Sales_data___Copy[[#This Row],[Total_Orders_Per_Customer]],Table2[F-Cutoff],1) -> 5 | Y8: =MATCH(Auto_Sales_data___Copy[[#This Row],[Total_Sales_Per_Customer]],Table2[M-Cutoff],1) -> 5 | Z8: =Auto_Sales_data___Copy[[#This Row],[R-Score(1-5)]]&Auto_Sales_data___Copy[[#This Row],[F-Score(1-5)]]&Auto_Sales_data___Copy[[#This Row],[M-Score(1-5)]] -> 555 | AA8: {=_xlfn.IFS(OR(Auto_Sales_data___Copy[[#This Row],[R-Score(1-5)]]=5,Auto_Sales_data___Copy[[#This Row],[R-Score(1-5)]]=4)*AND(Auto_Sales_data___Copy[[#This Row],[F-Score(1-5)]]>=4,Auto_Sales_data___Copy[[#This Row],[M-Score(1-5)]]>=4),'Segments & Strategies'!$A$2,AND(Auto_Sales_data___Copy[[#This Row],[R-Score(1-5)]]=3,Auto_Sales_data___Copy[[#This Row],[F-Score(1-5)]]>=4,Auto_Sales_data___Copy[[#This Row],[M-Score(1-5)]]>=4),'Segments & Strategies'!$A$3,AND(Auto_Sales_data___Copy[[#This Row],[R-Score(1-5)]]>=4,Auto_Sales_data___Copy[[#This Row],[F-Score(1-5)]]=5,Auto_Sales_data___Copy[[#This Row],[M-Score(1-5)]]<=3),'Segments & Strategies'!$A$4, AND(Auto_Sales_data___Copy[[#This Row],[R-Score(1-5)]]=2,Auto_Sales_data___Copy[[#This Row],[F-Score(1-5)]]>=4,Auto_Sales_data___Copy[[#This Row],[M-Score(1-5)]]>=4),'Segments & Strategies'!$A$6,AND(Auto_Sales_data___Copy[[#This Row],[R-Score(1-5)]]=1,Auto_Sales_data___Copy[[#This Row],[F-Score(1-5)]]<=2,Auto_Sales_data___Copy[[#This Row],[M-Score(1-5)]]<=2),'Segments & Strategies'!$A$8,AND(Auto_Sales_data___Copy[[#This Row],[R-Score(1-5)]]<=3,Auto_Sales_data___Copy[[#This Row],[F-Score(1-5)]]<=3,Auto_Sales_data___Copy[[#This Row],[M-Score(1-5)]]<=2), 'Segments & Strategies'!$A$7, TRUE,'Segments & Strategies'!$A$5)} -> Champion | AB8: =VLOOKUP(Auto_Sales_data___Copy[[#This Row],[Segment Name]],Table3[],2,FALSE) -> VIP Recognitioon & Inclusivity | AF8: Land of Toys Inc. | AG8: 49 | AH8: 164069.44
A9: 10212 | B9: 39 | C9: 126.84 | D9: 16 | E9: 4946.76 | F9: 43481 | G9: Shipped | H9: Classic Cars | I9: 117 | J9: S12_3380 | K9: Euro Shopping Channel | L9: (91) 555 94 44 | M9: C/ Moralzarzal, 86 | N9: Madrid | O9: 28034 | P9: Spain | Q9: Freyre | R9: Diego | S9: Medium | T9: 785 | U9: =VLOOKUP(Auto_Sales_data___Copy[[#This Row],[CUSTOMER_NAME]],$AF$2:$AH$90,2,FALSE) -> 259 | V9: =VLOOKUP(Auto_Sales_data___Copy[[#This Row],[CUSTOMER_NAME]],$AF$2:$AH$90,3,FALSE) -> 912294.11 | W9: =6-MATCH(Auto_Sales_data___Copy[[#This Row],[DAYS_SINCE_LAST_ORDER]],Table2[R-Cutoff],1) -> 5 | X9: =MATCH(Auto_Sales_data___Copy[[#This Row],[Total_Orders_Per_Customer]],Table2[F-Cutoff],1) -> 5 | Y9: =MATCH(Auto_Sales_data___Copy[[#This Row],[Total_Sales_Per_Customer]],Table2[M-Cutoff],1) -> 5 | Z9: =Auto_Sales_data___Copy[[#This Row],[R-Score(1-5)]]&Auto_Sales_data___Copy[[#This Row],[F-Score(1-5)]]&Auto_Sales_data___Copy[[#This Row],[M-Score(1-5)]] -> 555 | AA9: {=_xlfn.IFS(OR(Auto_Sales_data___Copy[[#This Row],[R-Score(1-5)]]=5,Auto_Sales_data___Copy[[#This Row],[R-Score(1-5)]]=4)*AND(Auto_Sales_data___Copy[[#This Row],[F-Score(1-5)]]>=4,Auto_Sales_data___Copy[[#This Row],[M-Score(1-5)]]>=4),'Segments & Strategies'!$A$2,AND(Auto_Sales_data___Copy[[#This Row],[R-Score(1-5)]]=3,Auto_Sales_data___Copy[[#This Row],[F-Score(1-5)]]>=4,Auto_Sales_data___Copy[[#This Row],[M-Score(1-5)]]>=4),'Segments & Strategies'!$A$3,AND(Auto_Sales_data___Copy[[#This Row],[R-Score(1-5)]]>=4,Auto_Sales_data___Copy[[#This Row],[F-Score(1-5)]]=5,Auto_Sales_data___Copy[[#This Row],[M-Score(1-5)]]<=3),'Segments & Strategies'!$A$4, AND(Auto_Sales_data___Copy[[#This Row],[R-Score(1-5)]]=2,Auto_Sales_data___Copy[[#This Row],[F-Score(1-5)]]>=4,Auto_Sales_data___Copy[[#This Row],[M-Score(1-5)]]>=4),'Segments & Strategies'!$A$6,AND(Auto_Sales_data___Copy[[#This Row],[R-Score(1-5)]]=1,Auto_Sales_data___Copy[[#This Row],[F-Score(1-5)]]<=2,Auto_Sales_data___Copy[[#This Row],[M-Score(1-5)]]<=2),'Segments & Strategies'!$A$8,AND(Auto_Sales_data___Copy[[#This Row],[R-Score(1-5)]]<=3,Auto_Sales_data___Copy[[#This Row],[F-Score(1-5)]]<=3,Auto_Sales_data___Copy[[#This Row],[M-Score(1-5)]]<=2), 'Segments & Strategies'!$A$7, TRUE,'Segments & Strategies'!$A$5)} -> Champion | AB9: =VLOOKUP(Auto_Sales_data___Copy[[#This Row],[Segment Name]],Table3[],2,FALSE) -> VIP Recognitioon & Inclusivity | AF9: The Sharp Gifts Warehouse | AG9: 40 | AH9: 160010.27
A10: 10212 | B10: 33 | C10: 126.68 | D10: 15 | E10: 4180.44 | F10: 43481 | G10: Shipped | H10: Classic Cars | I10: 115 | J10: S12_4675 | K10: Euro Shopping Channel | L10: (91) 555 94 44 | M10: C/ Moralzarzal, 86 | N10: Madrid | O10: 28034 | P10: Spain | Q10: Freyre | R10: Diego | S10: Medium | T10: 886 | U10: =VLOOKUP(Auto_Sales_data___Copy[[#This Row],[CUSTOMER_NAME]],$AF$2:$AH$90,2,FALSE) -> 259 | V10: =VLOOKUP(Auto_Sales_data___Copy[[#This Row],[CUSTOMER_NAME]],$AF$2:$AH$90,3,FALSE) -> 912294.11 | W10: =6-MATCH(Auto_Sales_data___Copy[[#This Row],[DAYS_SINCE_LAST_ORDER]],Table2[R-Cutoff],1) -> 5 | X10: =MATCH(Auto_Sales_data___Copy[[#This Row],[Total_Orders_Per_Customer]],Table2[F-Cutoff],1) -> 5 | Y10: =MATCH(Auto_Sales_data___Copy[[#This Row],[Total_Sales_Per_Customer]],Table2[M-Cutoff],1) -> 5 | Z10: =Auto_Sales_data___Copy[[#This Row],[R-Score(1-5)]]&Auto_Sales_data___Copy[[#This Row],[F-Score(1-5)]]&Auto_Sales_data___Copy[[#This Row],[M-Score(1-5)]] -> 555 | AA10: {=_xlfn.IFS(OR(Auto_Sales_data___Copy[[#This Row],[R-Score(1-5)]]=5,Auto_Sales_data___Copy[[#This Row],[R-Score(1-5)]]=4)*AND(Auto_Sales_data___Copy[[#This Row],[F-Score(1-5)]]>=4,Auto_Sales_data___Copy[[#This Row],[M-Score(1-5)]]>=4),'Segments & Strategies'!$A$2,AND(Auto_Sales_data___Copy[[#This Row],[R-Score(1-5)]]=3,Auto_Sales_data___Copy[[#This Row],[F-Score(1-5)]]>=4,Auto_Sales_data___Copy[[#This Row],[M-Score(1-5)]]>=4),'Segments & Strategies'!$A$3,AND(Auto_Sales_data___Copy[[#This Row],[R-Score(1-5)]]>=4,Auto_Sales_data___Copy[[#This Row],[F-Score(1-5)]]=5,Auto_Sales_data___Copy[[#This Row],[M-Score(1-5)]]<=3),'Segments & Strategies'!$A$4, AND(Auto_Sales_data___Copy[[#This Row],[R-Score(1-5)]]=2,Auto_Sales_data___Copy[[#This Row],[F-Score(1-5)]]>=4,Auto_Sales_data___Copy[[#This Row],[M-Score(1-5)]]>=4),'Segments & Strategies'!$A$6,AND(Auto_Sales_data___Copy[[#This Row],[R-Score(1-5)]]=1,Auto_Sales_data___Copy[[#This Row],[F-Score(1-5)]]<=2,Auto_Sales_data___Copy[[#This Row],[M-Score(1-5)]]<=2),'Segments & Strategies'!$A$8,AND(Auto_Sales_data___Copy[[#This Row],[R-Score(1-5)]]<=3,Auto_Sales_data___Copy[[#This Row],[F-Score(1-5)]]<=3,Auto_Sales_data___Copy[[#This Row],[M-Score(1-5)]]<=2), 'Segments & Strategies'!$A$7, TRUE,'Segments & Strategies'!$A$5)} -> Champion | AB10: =VLOOKUP(Auto_Sales_data___Copy[[#This Row],[Segment Name]],Table3[],2,FALSE) -> VIP Recognitioon & Inclusivity | AF10: AV Stores, Co. | AG10: 51 | AH10: 157807.81
A11: 10212 | B11: 29 | C11: 144.37 | D11: 10 | E11: 4186.73 | F11: 43481 | G11: Shipped | H11: Classic Cars | I11: 141 | J11: S18_1129 | K11: Euro Shopping Channel | L11: (91) 555 94 44 | M11: C/ Moralzarzal, 86 | N11: Madrid | O11: 28034 | P11: Spain | Q11: Freyre | R11: Diego | S11: Medium | T11: 938 | U11: =VLOOKUP(Auto_Sales_data___Copy[[#This Row],[CUSTOMER_NAME]],$AF$2:$AH$90,2,FALSE) -> 259 | V11: =VLOOKUP(Auto_Sales_data___Copy[[#This Row],[CUSTOMER_NAME]],$AF$2:$AH$90,3,FALSE) -> 912294.11 | W11: =6-MATCH(Auto_Sales_data___Copy[[#This Row],[DAYS_SINCE_LAST_ORDER]],Table2[R-Cutoff],1) -> 5 | X11: =MATCH(Auto_Sales_data___Copy[[#This Row],[Total_Orders_Per_Customer]],Table2[F-Cutoff],1) -> 5 | Y11: =MATCH(Auto_Sales_data___Copy[[#This Row],[Total_Sales_Per_Customer]],Table2[M-Cutoff],1) -> 5 | Z11: =Auto_Sales_data___Copy[[#This Row],[R-Score(1-5)]]&Auto_Sales_data___Copy[[#This Row],[F-Score(1-5)]]&Auto_Sales_data___Copy[[#This Row],[M-Score(1-5)]] -> 555 | AA11: {=_xlfn.IFS(OR(Auto_Sales_data___Copy[[#This Row],[R-Score(1-5)]]=5,Auto_Sales_data___Copy[[#This Row],[R-Score(1-5)]]=4)*AND(Auto_Sales_data___Copy[[#This Row],[F-Score(1-5)]]>=4,Auto_Sales_data___Copy[[#This Row],[M-Score(1-5)]]>=4),'Segments & Strategies'!$A$2,AND(Auto_Sales_data___Copy[[#This Row],[R-Score(1-5)]]=3,Auto_Sales_data___Copy[[#This Row],[F-Score(1-5)]]>=4,Auto_Sales_data___Copy[[#This Row],[M-Score(1-5)]]>=4),'Segments & Strategies'!$A$3,AND(Auto_Sales_data___Copy[[#This Row],[R-Score(1-5)]]>=4,Auto_Sales_data___Copy[[#This Row],[F-Score(1-5)]]=5,Auto_Sales_data___Copy[[#This Row],[M-Score(1-5)]]<=3),'Segments & Strategies'!$A$4, AND(Auto_Sales_data___Copy[[#This Row],[R-Score(1-5)]]=2,Auto_Sales_data___Copy[[#This Row],[F-Score(1-5)]]>=4,Auto_Sales_data___Copy[[#This Row],[M-Score(1-5)]]>=4),'Segments & Strategies'!$A$6,AND(Auto_Sales_data___Copy[[#This Row],[R-Score(1-5)]]=1,Auto_Sales_data___Copy[[#This Row],[F-Score(1-5)]]<=2,Auto_Sales_data___Copy[[#This Row],[M-Score(1-5)]]<=2),'Segments & Strategies'!$A$8,AND(Auto_Sales_data___Copy[[#This Row],[R-Score(1-5)]]<=3,Auto_Sales_data___Copy[[#This Row],[F-Score(1-5)]]<=3,Auto_Sales_data___Copy[[#This Row],[M-Score(1-5)]]<=2), 'Segments & Strategies'!$A$7, TRUE,'Segments & Strategies'!$A$5)} -> Champion | AB11: =VLOOKUP(Auto_Sales_data___Copy[[#This Row],[Segment Name]],Table3[],2,FALSE) -> VIP Recognitioon & Inclusivity | AF11: Anna's Decorations, Ltd | AG11: 46 | AH11: 153996.13
A12: 10244 | B12: 40 | C12: 117.12 | D12: 7 | E12: 4684.8 | F12: 43584 | G12: Shipped | H12: Vintage Cars | I12: 102 | J12: S18_1342 | K12: Euro Shopping Channel | L12: (91) 555 94 44 | M12: C/ Moralzarzal, 86 | N12: Madrid | O12: 28034 | P12: Spain | Q12: Freyre | R12: Diego | S12: Medium | T12: 863 | U12: =VLOOKUP(Auto_Sales_data___Copy[[#This Row],[CUSTOMER_NAME]],$AF$2:$AH$90,2,FALSE) -> 259 | V12: =VLOOKUP(Auto_Sales_data___Copy[[#This Row],[CUSTOMER_NAME]],$AF$2:$AH$90,3,FALSE) -> 912294.11 | W12: =6-MATCH(Auto_Sales_data___Copy[[#This Row],[DAYS_SINCE_LAST_ORDER]],Table2[R-Cutoff],1) -> 5 | X12: =MATCH(Auto_Sales_data___Copy[[#This Row],[Total_Orders_Per_Customer]],Table2[F-Cutoff],1) -> 5 | Y12: =MATCH(Auto_Sales_data___Copy[[#This Row],[Total_Sales_Per_Customer]],Table2[M-Cutoff],1) -> 5 | Z12: =Auto_Sales_data___Copy[[#This Row],[R-Score(1-5)]]&Auto_Sales_data___Copy[[#This Row],[F-Score(1-5)]]&Auto_Sales_data___Copy[[#This Row],[M-Score(1-5)]] -> 555 | AA12: {=_xlfn.IFS(OR(Auto_Sales_data___Copy[[#This Row],[R-Score(1-5)]]=5,Auto_Sales_data___Copy[[#This Row],[R-Score(1-5)]]=4)*AND(Auto_Sales_data___Copy[[#This Row],[F-Score(1-5)]]>=4,Auto_Sales_data___Copy[[#This Row],[M-Score(1-5)]]>=4),'Segments & Strategies'!$A$2,AND(Auto_Sales_data___Copy[[#This Row],[R-Score(1-5)]]=3,Auto_Sales_data___Copy[[#This Row],[F-Score(1-5)]]>=4,Auto_Sales_data___Copy[[#This Row],[M-Score(1-5)]]>=4),'Segments & Strategies'!$A$3,AND(Auto_Sales_data___Copy[[#This Row],[R-Score(1-5)]]>=4,Auto_Sales_data___Copy[[#This Row],[F-Score(1-5)]]=5,Auto_Sales_data___Copy[[#This Row],[M-Score(1-5)]]<=3),'Segments & Strategies'!$A$4, AND(Auto_Sales_data___Copy[[#This Row],[R-Score(1-5)]]=2,Auto_Sales_data___Copy[[#This Row],[F-Score(1-5)]]>=4,Auto_Sales_data___Copy[[#This Row],[M-Score(1-5)]]>=4),'Segments & Strategies'!$A$6,AND(Auto_Sales_data___Copy[[#This Row],[R-Score(1-5)]]=1,Auto_Sales_data___Copy[[#This Row],[F-Score(1-5)]]<=2,Auto_Sales_data___Copy[[#This Row],[M-Score(1-5)]]<=2),'Segments & Strategies'!$A$8,AND(Auto_Sales_data___Copy[[#This Row],[R-Score(1-5)]]<=3,Auto_Sales_data___Copy[[#This Row],[F-Score(1-5)]]<=3,Auto_Sales_data___Copy[[#This Row],[M-Score(1-5)]]<=2), 'Segments & Strategies'!$A$7, TRUE,'Segments & Strategies'!$A$5)} -> Champion | AB12: =VLOOKUP(Auto_Sales_data___Copy[[#This Row],[Segment Name]],Table3[],2,FALSE) -> VIP Recognitioon & Inclusivity | AF12: Souveniers And Things Co. | AG12: 46 | AH12: 151570.98
A13: 10244 | B13: 20 | C13: 58.22 | D13: 6 | E13: 1164.4 | F13: 43584 | G13: Shipped | H13: Vintage Cars | I13: 53 | J13: S18_1367 | K13: Euro Shopping Channel | L13: (91) 555 94 44 | M13: C/ Moralzarzal, 86 | N13: Madrid | O13: 28034 | P13: Spain | Q13: Freyre | R13: Diego | S13: Small | T13: 887 | U13: =VLOOKUP(Auto_Sales_data___Copy[[#This Row],[CUSTOMER_NAME]],$AF$2:$AH$90,2,FALSE) -> 259 | V13: =VLOOKUP(Auto_Sales_data___Copy[[#This Row],[CUSTOMER_NAME]],$AF$2:$AH$90,3,FALSE) -> 912294.11 | W13: =6-MATCH(Auto_Sales_data___Copy[[#This Row],[DAYS_SINCE_LAST_ORDER]],Table2[R-Cutoff],1) -> 5 | X13: =MATCH(Auto_Sales_data___Copy[[#This Row],[Total_Orders_Per_Customer]],Table2[F-Cutoff],1) -> 5 | Y13: =MATCH(Auto_Sales_data___Copy[[#This Row],[Total_Sales_Per_Customer]],Table2[M-Cutoff],1) -> 5 | Z13: =Auto_Sales_data___Copy[[#This Row],[R-Score(1-5)]]&Auto_Sales_data___Copy[[#This Row],[F-Score(1-5)]]&Auto_Sales_data___Copy[[#This Row],[M-Score(1-5)]] -> 555 | AA13: {=_xlfn.IFS(OR(Auto_Sales_data___Copy[[#This Row],[R-Score(1-5)]]=5,Auto_Sales_data___Copy[[#This Row],[R-Score(1-5)]]=4)*AND(Auto_Sales_data___Copy[[#This Row],[F-Score(1-5)]]>=4,Auto_Sales_data___Copy[[#This Row],[M-Score(1-5)]]>=4),'Segments & Strategies'!$A$2,AND(Auto_Sales_data___Copy[[#This Row],[R-Score(1-5)]]=3,Auto_Sales_data___Copy[[#This Row],[F-Score(1-5)]]>=4,Auto_Sales_data___Copy[[#This Row],[M-Score(1-5)]]>=4),'Segments & Strategies'!$A$3,AND(Auto_Sales_data___Copy[[#This Row],[R-Score(1-5)]]>=4,Auto_Sales_data___Copy[[#This Row],[F-Score(1-5)]]=5,Auto_Sales_data___Copy[[#This Row],[M-Score(1-5)]]<=3),'Segments & Strategies'!$A$4, AND(Auto_Sales_data___Copy[[#This Row],[R-Score(1-5)]]=2,Auto_Sales_data___Copy[[#This Row],[F-Score(1-5)]]>=4,Auto_Sales_data___Copy[[#This Row],[M-Score(1-5)]]>=4),'Segments & Strategies'!$A$6,AND(Auto_Sales_data___Copy[[#This Row],[R-Score(1-5)]]=1,Auto_Sales_data___Copy[[#This Row],[F-Score(1-5)]]<=2,Auto_Sales_data___Copy[[#This Row],[M-Score(1-5)]]<=2),'Segments & Strategies'!$A$8,AND(Auto_Sales_data___Copy[[#This Row],[R-Score(1-5)]]<=3,Auto_Sales_data___Copy[[#This Row],[F-Score(1-5)]]<=3,Auto_Sales_data___Copy[[#This Row],[M-Score(1-5)]]<=2), 'Segments & Strategies'!$A$7, TRUE,'Segments & Strategies'!$A$5)} -> Champion | AB13: =VLOOKUP(Auto_Sales_data___Copy[[#This Row],[Segment Name]],Table3[],2,FALSE) -> VIP Recognitioon & Inclusivity | AF13: Salzburg Collectables | AG13: 40 | AH13: 149798.63
... A91: 10188 | B91: 38 | C91: 96.34 | D91: 4 | E91: 3660.92 | F91: 43422 | G91: Shipped | H91: Motorcycles | I91: 118 | J91: S10_2016 | K91: Herkku Gifts | L91: +47 2267 3215 | M91: Drammen 121, PR 744 Sentrum | N91: Bergen | O91: N 5804 | P91: Norway | Q91: Oeztan | R91: Veysel | S91: Medium | T91: 617 | U91: =VLOOKUP(Auto_Sales_data___Copy[[#This Row],[CUSTOMER_NAME]],$AF$2:$AH$90,2,FALSE) -> 29 | V91: =VLOOKUP(Auto_Sales_data___Copy[[#This Row],[CUSTOMER_NAME]],$AF$2:$AH$90,3,FALSE) -> 111640.28 | W91: =6-MATCH(Auto_Sales_data___Copy[[#This Row],[DAYS_SINCE_LAST_ORDER]],Table2[R-Cutoff],1) -> 5 | X91: =MATCH(Auto_Sales_data___Copy[[#This Row],[Total_Orders_Per_Customer]],Table2[F-Cutoff],1) -> 4 | Y91: =MATCH(Auto_Sales_data___Copy[[#This Row],[Total_Sales_Per_Customer]],Table2[M-Cutoff],1) -> 4 | Z91: =Auto_Sales_data___Copy[[#This Row],[R-Score(1-5)]]&Auto_Sales_data___Copy[[#This Row],[F-Score(1-5)]]&Auto_Sales_data___Copy[[#This Row],[M-Score(1-5)]] -> 544 | AA91: {=_xlfn.IFS(OR(Auto_Sales_data___Copy[[#This Row],[R-Score(1-5)]]=5,Auto_Sales_data___Copy[[#This Row],[R-Score(1-5)]]=4)*AND(Auto_Sales_data___Copy[[#This Row],[F-Score(1-5)]]>=4,Auto_Sales_data___Copy[[#This Row],[M-Score(1-5)]]>=4),'Segments & Strategies'!$A$2,AND(Auto_Sales_data___Copy[[#This Row],[R-Score(1-5)]]=3,Auto_Sales_data___Copy[[#This Row],[F-Score(1-5)]]>=4,Auto_Sales_data___Copy[[#This Row],[M-Score(1-5)]]>=4),'Segments & Strategies'!$A$3,AND(Auto_Sales_data___Copy[[#This Row],[R-Score(1-5)]]>=4,Auto_Sales_data___Copy[[#This Row],[F-Score(1-5)]]=5,Auto_Sales_data___Copy[[#This Row],[M-Score(1-5)]]<=3),'Segments & Strategies'!$A$4, AND(Auto_Sales_data___Copy[[#This Row],[R-Score(1-5)]]=2,Auto_Sales_data___Copy[[#This Row],[F-Score(1-5)]]>=4,Auto_Sales_data___Copy[[#This Row],[M-Score(1-5)]]>=4),'Segments & Strategies'!$A$6,AND(Auto_Sales_data___Copy[[#This Row],[R-Score(1-5)]]=1,Auto_Sales_data___Copy[[#This Row],[F-Score(1-5)]]<=2,Auto_Sales_data___Copy[[#This Row],[M-Score(1-5)]]<=2),'Segments & Strategies'!$A$8,AND(Auto_Sales_data___Copy[[#This Row],[R-Score(1-5)]]<=3,Auto_Sales_data___Copy[[#This Row],[F-Score(1-5)]]<=3,Auto_Sales_data___Copy[[#This Row],[M-Score(1-5)]]<=2), 'Segments & Strategies'!$A$7, TRUE,'Segments & Strategies'!$A$5)} -> Champion | AB91: =VLOOKUP(Auto_Sales_data___Copy[[#This Row],[Segment Name]],Table3[],2,FALSE) -> VIP Recognitioon & Inclusivity | AF91: Grand Total | AG91: 2747 | AH91: 9760221.7
A92: 10188 | B92: 45 | C92: 193.66 | D92: 3 | E92: 8714.7 | F92: 43422 | G92: Shipped | H92: Motorcycles | I92: 193 | J92: S10_4698 | K92: Herkku Gifts | L92: +47 2267 3215 | M92: Drammen 121, PR 744 Sentrum | N92: Bergen | O92: N 5804 | P92: Norway | Q92: Oeztan | R92: Veysel | S92: Large | T92: 641 | U92: =VLOOKUP(Auto_Sales_data___Copy[[#This Row],[CUSTOMER_NAME]],$AF$2:$AH$90,2,FALSE) -> 29 | V92: =VLOOKUP(Auto_Sales_data___Copy[[#This Row],[CUSTOMER_NAME]],$AF$2:$AH$90,3,FALSE) -> 111640.28 | W92: =6-MATCH(Auto_Sales_data___Copy[[#This Row],[DAYS_SINCE_LAST_ORDER]],Table2[R-Cutoff],1) -> 5 | X92: =MATCH(Auto_Sales_data___Copy[[#This Row],[Total_Orders_Per_Customer]],Table2[F-Cutoff],1) -> 4 | Y92: =MATCH(Auto_Sales_data___Copy[[#This Row],[Total_Sales_Per_Customer]],Table2[M-Cutoff],1) -> 4 | Z92: =Auto_Sales_data___Copy[[#This Row],[R-Score(1-5)]]&Auto_Sales_data___Copy[[#This Row],[F-Score(1-5)]]&Auto_Sales_data___Copy[[#This Row],[M-Score(1-5)]] -> 544 | AA92: {=_xlfn.IFS(OR(Auto_Sales_data___Copy[[#This Row],[R-Score(1-5)]]=5,Auto_Sales_data___Copy[[#This Row],[R-Score(1-5)]]=4)*AND(Auto_Sales_data___Copy[[#This Row],[F-Score(1-5)]]>=4,Auto_Sales_data___Copy[[#This Row],[M-Score(1-5)]]>=4),'Segments & Strategies'!$A$2,AND(Auto_Sales_data___Copy[[#This Row],[R-Score(1-5)]]=3,Auto_Sales_data___Copy[[#This Row],[F-Score(1-5)]]>=4,Auto_Sales_data___Copy[[#This Row],[M-Score(1-5)]]>=4),'Segments & Strategies'!$A$3,AND(Auto_Sales_data___Copy[[#This Row],[R-Score(1-5)]]>=4,Auto_Sales_data___Copy[[#This Row],[F-Score(1-5)]]=5,Auto_Sales_data___Copy[[#This Row],[M-Score(1-5)]]<=3),'Segments & Strategies'!$A$4, AND(Auto_Sales_data___Copy[[#This Row],[R-Score(1-5)]]=2,Auto_Sales_data___Copy[[#This Row],[F-Score(1-5)]]>=4,Auto_Sales_data___Copy[[#This Row],[M-Score(1-5)]]>=4),'Segments & Strategies'!$A$6,AND(Auto_Sales_data___Copy[[#This Row],[R-Score(1-5)]]=1,Auto_Sales_data___Copy[[#This Row],[F-Score(1-5)]]<=2,Auto_Sales_data___Copy[[#This Row],[M-Score(1-5)]]<=2),'Segments & Strategies'!$A$8,AND(Auto_Sales_data___Copy[[#This Row],[R-Score(1-5)]]<=3,Auto_Sales_data___Copy[[#This Row],[F-Score(1-5)]]<=3,Auto_Sales_data___Copy[[#This Row],[M-Score(1-5)]]<=2), 'Segments & Strategies'!$A$7, TRUE,'Segments & Strategies'!$A$5)} -> Champion | AB92: =VLOOKUP(Auto_Sales_data___Copy[[#This Row],[Segment Name]],Table3[],2,FALSE) -> VIP Recognitioon & Inclusivity
A93: 10189 | B93: 28 | C93: 161.16 | D93: 1 | E93: 4512.48 | F93: 43422 | G93: Shipped | H93: Motorcycles | I93: 150 | J93: S12_2823 | K93: Toys4GrownUps.com | L93: 6265557265 | M93: 78934 Hillside Dr. | N93: Pasadena | O93: 90003 | P93: USA | Q93: Young | R93: Julie | S93: Medium | T93: 793 | U93: =VLOOKUP(Auto_Sales_data___Copy[[#This Row],[CUSTOMER_NAME]],$AF$2:$AH$90,2,FALSE) -> 30 | V93: =VLOOKUP(Auto_Sales_data___Copy[[#This Row],[CUSTOMER_NAME]],$AF$2:$AH$90,3,FALSE) -> 104561.96 | W93: =6-MATCH(Auto_Sales_data___Copy[[#This Row],[DAYS_SINCE_LAST_ORDER]],Table2[R-Cutoff],1) -> 5 | X93: =MATCH(Auto_Sales_data___Copy[[#This Row],[Total_Orders_Per_Customer]],Table2[F-Cutoff],1) -> 4 | Y93: =MATCH(Auto_Sales_data___Copy[[#This Row],[Total_Sales_Per_Customer]],Table2[M-Cutoff],1) -> 4 | Z93: =Auto_Sales_data___Copy[[#This Row],[R-Score(1-5)]]&Auto_Sales_data___Copy[[#This Row],[F-Score(1-5)]]&Auto_Sales_data___Copy[[#This Row],[M-Score(1-5)]] -> 544 | AA93: {=_xlfn.IFS(OR(Auto_Sales_data___Copy[[#This Row],[R-Score(1-5)]]=5,Auto_Sales_data___Copy[[#This Row],[R-Score(1-5)]]=4)*AND(Auto_Sales_data___Copy[[#This Row],[F-Score(1-5)]]>=4,Auto_Sales_data___Copy[[#This Row],[M-Score(1-5)]]>=4),'Segments & Strategies'!$A$2,AND(Auto_Sales_data___Copy[[#This Row],[R-Score(1-5)]]=3,Auto_Sales_data___Copy[[#This Row],[F-Score(1-5)]]>=4,Auto_Sales_data___Copy[[#This Row],[M-Score(1-5)]]>=4),'Segments & Strategies'!$A$3,AND(Auto_Sales_data___Copy[[#This Row],[R-Score(1-5)]]>=4,Auto_Sales_data___Copy[[#This Row],[F-Score(1-5)]]=5,Auto_Sales_data___Copy[[#This Row],[M-Score(1-5)]]<=3),'Segments & Strategies'!$A$4, AND(Auto_Sales_data___Copy[[#This Row],[R-Score(1-5)]]=2,Auto_Sales_data___Copy[[#This Row],[F-Score(1-5)]]>=4,Auto_Sales_data___Copy[[#This Row],[M-Score(1-5)]]>=4),'Segments & Strategies'!$A$6,AND(Auto_Sales_data___Copy[[#This Row],[R-Score(1-5)]]=1,Auto_Sales_data___Copy[[#This Row],[F-Score(1-5)]]<=2,Auto_Sales_data___Copy[[#This Row],[M-Score(1-5)]]<=2),'Segments & Strategies'!$A$8,AND(Auto_Sales_data___Copy[[#This Row],[R-Score(1-5)]]<=3,Auto_Sales_data___Copy[[#This Row],[F-Score(1-5)]]<=3,Auto_Sales_data___Copy[[#This Row],[M-Score(1-5)]]<=2), 'Segments & Strategies'!$A$7, TRUE,'Segments & Strategies'!$A$5)} -> Champion | AB93: =VLOOKUP(Auto_Sales_data___Copy[[#This Row],[Segment Name]],Table3[],2,FALSE) -> VIP Recognitioon & Inclusivity
A94: 10194 | B94: 42 | C94: 173.58 | D94: 11 | E94: 7290.36 | F94: 43429 | G94: Shipped | H94: Classic Cars | I94: 214 | J94: S10_1949 | K94: Saveley & Henriot, Co. | L94: 78.32.5555 | M94: 2, rue du Commerce | N94: Lyon | O94: 69004 | P94: France | Q94: Saveley | R94: Mary | S94: Large | T94: 586 | U94: =VLOOKUP(Auto_Sales_data___Copy[[#This Row],[CUSTOMER_NAME]],$AF$2:$AH$90,2,FALSE) -> 41 | V94: =VLOOKUP(Auto_Sales_data___Copy[[#This Row],[CUSTOMER_NAME]],$AF$2:$AH$90,3,FALSE) -> 142874.25 | W94: =6-MATCH(Auto_Sales_data___Copy[[#This Row],[DAYS_SINCE_LAST_ORDER]],Table2[R-Cutoff],1) -> 5 | X94: =MATCH(Auto_Sales_data___Copy[[#This Row],[Total_Orders_Per_Customer]],Table2[F-Cutoff],1) -> 4 | Y94: =MATCH(Auto_Sales_data___Copy[[#This Row],[Total_Sales_Per_Customer]],Table2[M-Cutoff],1) -> 4 | Z94: =Auto_Sales_data___Copy[[#This Row],[R-Score(1-5)]]&Auto_Sales_data___Copy[[#This Row],[F-Score(1-5)]]&Auto_Sales_data___Copy[[#This Row],[M-Score(1-5)]] -> 544 | AA94: {=_xlfn.IFS(OR(Auto_Sales_data___Copy[[#This Row],[R-Score(1-5)]]=5,Auto_Sales_data___Copy[[#This Row],[R-Score(1-5)]]=4)*AND(Auto_Sales_data___Copy[[#This Row],[F-Score(1-5)]]>=4,Auto_Sales_data___Copy[[#This Row],[M-Score(1-5)]]>=4),'Segments & Strategies'!$A$2,AND(Auto_Sales_data___Copy[[#This Row],[R-Score(1-5)]]=3,Auto_Sales_data___Copy[[#This Row],[F-Score(1-5)]]>=4,Auto_Sales_data___Copy[[#This Row],[M-Score(1-5)]]>=4),'Segments & Strategies'!$A$3,AND(Auto_Sales_data___Copy[[#This Row],[R-Score(1-5)]]>=4,Auto_Sales_data___Copy[[#This Row],[F-Score(1-5)]]=5,Auto_Sales_data___Copy[[#This Row],[M-Score(1-5)]]<=3),'Segments & Strategies'!$A$4, AND(Auto_Sales_data___Copy[[#This Row],[R-Score(1-5)]]=2,Auto_Sales_data___Copy[[#This Row],[F-Score(1-5)]]>=4,Auto_Sales_data___Copy[[#This Row],[M-Score(1-5)]]>=4),'Segments & Strategies'!$A$6,AND(Auto_Sales_data___Copy[[#This Row],[R-Score(1-5)]]=1,Auto_Sales_data___Copy[[#This Row],[F-Score(1-5)]]<=2,Auto_Sales_data___Copy[[#This Row],[M-Score(1-5)]]<=2),'Segments & Strategies'!$A$8,AND(Auto_Sales_data___Copy[[#This Row],[R-Score(1-5)]]<=3,Auto_Sales_data___Copy[[#This Row],[F-Score(1-5)]]<=3,Auto_Sales_data___Copy[[#This Row],[M-Score(1-5)]]<=2), 'Segments & Strategies'!$A$7, TRUE,'Segments & Strategies'!$A$5)} -> Champion | AB94: =VLOOKUP(Auto_Sales_data___Copy[[#This Row],[Segment Name]],Table3[],2,FALSE) -> VIP Recognitioon & Inclusivity
A95: 10194 | B95: 26 | C95: 163.99 | D95: 4 | E95: 4263.74 | F95: 43429 | G95: Shipped | H95: Classic Cars | I95: 147 | J95: S10_4962 | K95: Saveley & Henriot, Co. | L95: 78.32.5555 | M95: 2, rue du Commerce | N95: Lyon | O95: 69004 | P95: France | Q95: Saveley | R95: Mary | S95: Medium | T95: 685 | U95: =VLOOKUP(Auto_Sales_data___Copy[[#This Row],[CUSTOMER_NAME]],$AF$2:$AH$90,2,FALSE) -> 41 | V95: =VLOOKUP(Auto_Sales_data___Copy[[#This Row],[CUSTOMER_NAME]],$AF$2:$AH$90,3,FALSE) -> 142874.25 | W95: =6-MATCH(Auto_Sales_data___Copy[[#This Row],[DAYS_SINCE_LAST_ORDER]],Table2[R-Cutoff],1) -> 5 | X95: =MATCH(Auto_Sales_data___Copy[[#This Row],[Total_Orders_Per_Customer]],Table2[F-Cutoff],1) -> 4 | Y95: =MATCH(Auto_Sales_data___Copy[[#This Row],[Total_Sales_Per_Customer]],Table2[M-Cutoff],1) -> 4 | Z95: =Auto_Sales_data___Copy[[#This Row],[R-Score(1-5)]]&Auto_Sales_data___Copy[[#This Row],[F-Score(1-5)]]&Auto_Sales_data___Copy[[#This Row],[M-Score(1-5)]] -> 544 | AA95: {=_xlfn.IFS(OR(Auto_Sales_data___Copy[[#This Row],[R-Score(1-5)]]=5,Auto_Sales_data___Copy[[#This Row],[R-Score(1-5)]]=4)*AND(Auto_Sales_data___Copy[[#This Row],[F-Score(1-5)]]>=4,Auto_Sales_data___Copy[[#This Row],[M-Score(1-5)]]>=4),'Segments & Strategies'!$A$2,AND(Auto_Sales_data___Copy[[#This Row],[R-Score(1-5)]]=3,Auto_Sales_data___Copy[[#This Row],[F-Score(1-5)]]>=4,Auto_Sales_data___Copy[[#This Row],[M-Score(1-5)]]>=4),'Segments & Strategies'!$A$3,AND(Auto_Sales_data___Copy[[#This Row],[R-Score(1-5)]]>=4,Auto_Sales_data___Copy[[#This Row],[F-Score(1-5)]]=5,Auto_Sales_data___Copy[[#This Row],[M-Score(1-5)]]<=3),'Segments & Strategies'!$A$4, AND(Auto_Sales_data___Copy[[#This Row],[R-Score(1-5)]]=2,Auto_Sales_data___Copy[[#This Row],[F-Score(1-5)]]>=4,Auto_Sales_data___Copy[[#This Row],[M-Score(1-5)]]>=4),'Segments & Strategies'!$A$6,AND(Auto_Sales_data___Copy[[#This Row],[R-Score(1-5)]]=1,Auto_Sales_data___Copy[[#This Row],[F-Score(1-5)]]<=2,Auto_Sales_data___Copy[[#This Row],[M-Score(1-5)]]<=2),'Segments & Strategies'!$A$8,AND(Auto_Sales_data___Copy[[#This Row],[R-Score(1-5)]]<=3,Auto_Sales_data___Copy[[#This Row],[F-Score(1-5)]]<=3,Auto_Sales_data___Copy[[#This Row],[M-Score(1-5)]]<=2), 'Segments & Strategies'!$A$7, TRUE,'Segments & Strategies'!$A$5)} -> Champion | AB95: =VLOOKUP(Auto_Sales_data___Copy[[#This Row],[Segment Name]],Table3[],2,FALSE) -> VIP Recognitioon & Inclusivity
A96: 10194 | B96: 38 | C96: 129.84 | D96: 8 | E96: 4933.92 | F96: 43429 | G96: Shipped | H96: Trucks and Buses | I96: 136 | J96: S12_1666 | K96: Saveley & Henriot, Co. | L96: 78.32.5555 | M96: 2, rue du Commerce | N96: Lyon | O96: 69004 | P96: France | Q96: Saveley | R96: Mary | S96: Medium | T96: 762 | U96: =VLOOKUP(Auto_Sales_data___Copy[[#This Row],[CUSTOMER_NAME]],$AF$2:$AH$90,2,FALSE) -> 41 | V96: =VLOOKUP(Auto_Sales_data___Copy[[#This Row],[CUSTOMER_NAME]],$AF$2:$AH$90,3,FALSE) -> 142874.25 | W96: =6-MATCH(Auto_Sales_data___Copy[[#This Row],[DAYS_SINCE_LAST_ORDER]],Table2[R-Cutoff],1) -> 5 | X96: =MATCH(Auto_Sales_data___Copy[[#This Row],[Total_Orders_Per_Customer]],Table2[F-Cutoff],1) -> 4 | Y96: =MATCH(Auto_Sales_data___Copy[[#This Row],[Total_Sales_Per_Customer]],Table2[M-Cutoff],1) -> 4 | Z96: =Auto_Sales_data___Copy[[#This Row],[R-Score(1-5)]]&Auto_Sales_data___Copy[[#This Row],[F-Score(1-5)]]&Auto_Sales_data___Copy[[#This Row],[M-Score(1-5)]] -> 544 | AA96: {=_xlfn.IFS(OR(Auto_Sales_data___Copy[[#This Row],[R-Score(1-5)]]=5,Auto_Sales_data___Copy[[#This Row],[R-Score(1-5)]]=4)*AND(Auto_Sales_data___Copy[[#This Row],[F-Score(1-5)]]>=4,Auto_Sales_data___Copy[[#This Row],[M-Score(1-5)]]>=4),'Segments & Strategies'!$A$2,AND(Auto_Sales_data___Copy[[#This Row],[R-Score(1-5)]]=3,Auto_Sales_data___Copy[[#This Row],[F-Score(1-5)]]>=4,Auto_Sales_data___Copy[[#This Row],[M-Score(1-5)]]>=4),'Segments & Strategies'!$A$3,AND(Auto_Sales_data___Copy[[#This Row],[R-Score(1-5)]]>=4,Auto_Sales_data___Copy[[#This Row],[F-Score(1-5)]]=5,Auto_Sales_data___Copy[[#This Row],[M-Score(1-5)]]<=3),'Segments & Strategies'!$A$4, AND(Auto_Sales_data___Copy[[#This Row],[R-Score(1-5)]]=2,Auto_Sales_data___Copy[[#This Row],[F-Score(1-5)]]>=4,Auto_Sales_data___Copy[[#This Row],[M-Score(1-5)]]>=4),'Segments & Strategies'!$A$6,AND(Auto_Sales_data___Copy[[#This Row],[R-Score(1-5)]]=1,Auto_Sales_data___Copy[[#This Row],[F-Score(1-5)]]<=2,Auto_Sales_data___Copy[[#This Row],[M-Score(1-5)]]<=2),'Segments & Strategies'!$A$8,AND(Auto_Sales_data___Copy[[#This Row],[R-Score(1-5)]]<=3,Auto_Sales_data___Copy[[#This Row],[F-Score(1-5)]]<=3,Auto_Sales_data___Copy[[#This Row],[M-Score(1-5)]]<=2), 'Segments & Strategies'!$A$7, TRUE,'Segments & Strategies'!$A$5)} -> Champion | AB96: =VLOOKUP(Auto_Sales_data___Copy[[#This Row],[Segment Name]],Table3[],2,FALSE) -> VIP Recognitioon & Inclusivity
A97: 10208 | B97: 46 | C97: 187.02 | D97: 13 | E97: 8602.92 | F97: 43467 | G97: Shipped | H97: Classic Cars | I97: 207 | J97: S12_1108 | K97: Saveley & Henriot, Co. | L97: 78.32.5555 | M97: 2, rue du Commerce | N97: Lyon | O97: 69004 | P97: France | Q97: Saveley | R97: Mary | S97: Large | T97: 699 | U97: =VLOOKUP(Auto_Sales_data___Copy[[#This Row],[CUSTOMER_NAME]],$AF$2:$AH$90,2,FALSE) -> 41 | V97: =VLOOKUP(Auto_Sales_data___Copy[[#This Row],[CUSTOMER_NAME]],$AF$2:$AH$90,3,FALSE) -> 142874.25 | W97: =6-MATCH(Auto_Sales_data___Copy[[#This Row],[DAYS_SINCE_LAST_ORDER]],Table2[R-Cutoff],1) -> 5 | X97: =MATCH(Auto_Sales_data___Copy[[#This Row],[Total_Orders_Per_Customer]],Table2[F-Cutoff],1) -> 4 | Y97: =MATCH(Auto_Sales_data___Copy[[#This Row],[Total_Sales_Per_Customer]],Table2[M-Cutoff],1) -> 4 | Z97: =Auto_Sales_data___Copy[[#This Row],[R-Score(1-5)]]&Auto_Sales_data___Copy[[#This Row],[F-Score(1-5)]]&Auto_Sales_data___Copy[[#This Row],[M-Score(1-5)]] -> 544 | AA97: {=_xlfn.IFS(OR(Auto_Sales_data___Copy[[#This Row],[R-Score(1-5)]]=5,Auto_Sales_data___Copy[[#This Row],[R-Score(1-5)]]=4)*AND(Auto_Sales_data___Copy[[#This Row],[F-Score(1-5)]]>=4,Auto_Sales_data___Copy[[#This Row],[M-Score(1-5)]]>=4),'Segments & Strategies'!$A$2,AND(Auto_Sales_data___Copy[[#This Row],[R-Score(1-5)]]=3,Auto_Sales_data___Copy[[#This Row],[F-Score(1-5)]]>=4,Auto_Sales_data___Copy[[#This Row],[M-Score(1-5)]]>=4),'Segments & Strategies'!$A$3,AND(Auto_Sales_data___Copy[[#This Row],[R-Score(1-5)]]>=4,Auto_Sales_data___Copy[[#This Row],[F-Score(1-5)]]=5,Auto_Sales_data___Copy[[#This Row],[M-Score(1-5)]]<=3),'Segments & Strategies'!$A$4, AND(Auto_Sales_data___Copy[[#This Row],[R-Score(1-5)]]=2,Auto_Sales_data___Copy[[#This Row],[F-Score(1-5)]]>=4,Auto_Sales_data___Copy[[#This Row],[M-Score(1-5)]]>=4),'Segments & Strategies'!$A$6,AND(Auto_Sales_data___Copy[[#This Row],[R-Score(1-5)]]=1,Auto_Sales_data___Copy[[#This Row],[F-Score(1-5)]]<=2,Auto_Sales_data___Copy[[#This Row],[M-Score(1-5)]]<=2),'Segments & Strategies'!$A$8,AND(Auto_Sales_data___Copy[[#This Row],[R-Score(1-5)]]<=3,Auto_Sales_data___Copy[[#This Row],[F-Score(1-5)]]<=3,Auto_Sales_data___Copy[[#This Row],[M-Score(1-5)]]<=2), 'Segments & Strategies'!$A$7, TRUE,'Segments & Strategies'!$A$5)} -> Champion | AB97: =VLOOKUP(Auto_Sales_data___Copy[[#This Row],[Segment Name]],Table3[],2,FALSE) -> VIP Recognitioon & Inclusivity
A98: 10208 | B98: 26 | C98: 120.86 | D98: 14 | E98: 3142.36 | F98: 43467 | G98: Shipped | H98: Classic Cars | I98: 151 | J98: S12_3148 | K98: Saveley & Henriot, Co. | L98: 78.32.5555 | M98: 2, rue du Commerce | N98: Lyon | O98: 69004 | P98: France | Q98: Saveley | R98: Mary | S98: Medium | T98: 775 | U98: =VLOOKUP(Auto_Sales_data___Copy[[#This Row],[CUSTOMER_NAME]],$AF$2:$AH$90,2,FALSE) -> 41 | V98: =VLOOKUP(Auto_Sales_data___Copy[[#This Row],[CUSTOMER_NAME]],$AF$2:$AH$90,3,FALSE) -> 142874.25 | W98: =6-MATCH(Auto_Sales_data___Copy[[#This Row],[DAYS_SINCE_LAST_ORDER]],Table2[R-Cutoff],1) -> 5 | X98: =MATCH(Auto_Sales_data___Copy[[#This Row],[Total_Orders_Per_Customer]],Table2[F-Cutoff],1) -> 4 | Y98: =MATCH(Auto_Sales_data___Copy[[#This Row],[Total_Sales_Per_Customer]],Table2[M-Cutoff],1) -> 4 | Z98: =Auto_Sales_data___Copy[[#This Row],[R-Score(1-5)]]&Auto_Sales_data___Copy[[#This Row],[F-Score(1-5)]]&Auto_Sales_data___Copy[[#This Row],[M-Score(1-5)]] -> 544 | AA98: {=_xlfn.IFS(OR(Auto_Sales_data___Copy[[#This Row],[R-Score(1-5)]]=5,Auto_Sales_data___Copy[[#This Row],[R-Score(1-5)]]=4)*AND(Auto_Sales_data___Copy[[#This Row],[F-Score(1-5)]]>=4,Auto_Sales_data___Copy[[#This Row],[M-Score(1-5)]]>=4),'Segments & Strategies'!$A$2,AND(Auto_Sales_data___Copy[[#This Row],[R-Score(1-5)]]=3,Auto_Sales_data___Copy[[#This Row],[F-Score(1-5)]]>=4,Auto_Sales_data___Copy[[#This Row],[M-Score(1-5)]]>=4),'Segments & Strategies'!$A$3,AND(Auto_Sales_data___Copy[[#This Row],[R-Score(1-5)]]>=4,Auto_Sales_data___Copy[[#This Row],[F-Score(1-5)]]=5,Auto_Sales_data___Copy[[#This Row],[M-Score(1-5)]]<=3),'Segments & Strategies'!$A$4, AND(Auto_Sales_data___Copy[[#This Row],[R-Score(1-5)]]=2,Auto_Sales_data___Copy[[#This Row],[F-Score(1-5)]]>=4,Auto_Sales_data___Copy[[#This Row],[M-Score(1-5)]]>=4),'Segments & Strategies'!$A$6,AND(Auto_Sales_data___Copy[[#This Row],[R-Score(1-5)]]=1,Auto_Sales_data___Copy[[#This Row],[F-Score(1-5)]]<=2,Auto_Sales_data___Copy[[#This Row],[M-Score(1-5)]]<=2),'Segments & Strategies'!$A$8,AND(Auto_Sales_data___Copy[[#This Row],[R-Score(1-5)]]<=3,Auto_Sales_data___Copy[[#This Row],[F-Score(1-5)]]<=3,Auto_Sales_data___Copy[[#This Row],[M-Score(1-5)]]<=2), 'Segments & Strategies'!$A$7, TRUE,'Segments & Strategies'!$A$5)} -> Champion | AB98: =VLOOKUP(Auto_Sales_data___Copy[[#This Row],[Segment Name]],Table3[],2,FALSE) -> VIP Recognitioon & Inclusivity
A99: 10208 | B99: 20 | C99: 155.72 | D99: 12 | E99: 3114.4 | F99: 43467 | G99: Shipped | H99: Classic Cars | I99: 173 | J99: S12_3891 | K99: Saveley & Henriot, Co. | L99: 78.32.5555 | M99: 2, rue du Commerce | N99: Lyon | O99: 69004 | P99: France | Q99: Saveley | R99: Mary | S99: Medium | T99: 824 | U99: =VLOOKUP(Auto_Sales_data___Copy[[#This Row],[CUSTOMER_NAME]],$AF$2:$AH$90,2,FALSE) -> 41 | V99: =VLOOKUP(Auto_Sales_data___Copy[[#This Row],[CUSTOMER_NAME]],$AF$2:$AH$90,3,FALSE) -> 142874.25 | W99: =6-MATCH(Auto_Sales_data___Copy[[#This Row],[DAYS_SINCE_LAST_ORDER]],Table2[R-Cutoff],1) -> 5 | X99: =MATCH(Auto_Sales_data___Copy[[#This Row],[Total_Orders_Per_Customer]],Table2[F-Cutoff],1) -> 4 | Y99: =MATCH(Auto_Sales_data___Copy[[#This Row],[Total_Sales_Per_Customer]],Table2[M-Cutoff],1) -> 4 | Z99: =Auto_Sales_data___Copy[[#This Row],[R-Score(1-5)]]&Auto_Sales_data___Copy[[#This Row],[F-Score(1-5)]]&Auto_Sales_data___Copy[[#This Row],[M-Score(1-5)]] -> 544 | AA99: {=_xlfn.IFS(OR(Auto_Sales_data___Copy[[#This Row],[R-Score(1-5)]]=5,Auto_Sales_data___Copy[[#This Row],[R-Score(1-5)]]=4)*AND(Auto_Sales_data___Copy[[#This Row],[F-Score(1-5)]]>=4,Auto_Sales_data___Copy[[#This Row],[M-Score(1-5)]]>=4),'Segments & Strategies'!$A$2,AND(Auto_Sales_data___Copy[[#This Row],[R-Score(1-5)]]=3,Auto_Sales_data___Copy[[#This Row],[F-Score(1-5)]]>=4,Auto_Sales_data___Copy[[#This Row],[M-Score(1-5)]]>=4),'Segments & Strategies'!$A$3,AND(Auto_Sales_data___Copy[[#This Row],[R-Score(1-5)]]>=4,Auto_Sales_data___Copy[[#This Row],[F-Score(1-5)]]=5,Auto_Sales_data___Copy[[#This Row],[M-Score(1-5)]]<=3),'Segments & Strategies'!$A$4, AND(Auto_Sales_data___Copy[[#This Row],[R-Score(1-5)]]=2,Auto_Sales_data___Copy[[#This Row],[F-Score(1-5)]]>=4,Auto_Sales_data___Copy[[#This Row],[M-Score(1-5)]]>=4),'Segments & Strategies'!$A$6,AND(Auto_Sales_data___Copy[[#This Row],[R-Score(1-5)]]=1,Auto_Sales_data___Copy[[#This Row],[F-Score(1-5)]]<=2,Auto_Sales_data___Copy[[#This Row],[M-Score(1-5)]]<=2),'Segments & Strategies'!$A$8,AND(Auto_Sales_data___Copy[[#This Row],[R-Score(1-5)]]<=3,Auto_Sales_data___Copy[[#This Row],[F-Score(1-5)]]<=3,Auto_Sales_data___Copy[[#This Row],[M-Score(1-5)]]<=2), 'Segments & Strategies'!$A$7, TRUE,'Segments & Strategies'!$A$5)} -> Champion | AB99: =VLOOKUP(Auto_Sales_data___Copy[[#This Row],[Segment Name]],Table3[],2,FALSE) -> VIP Recognitioon & Inclusivity
A100: 10217 | B100: 48 | C100: 146.26 | D100: 4 | E100: 7020.48 | F100: 43500 | G100: Shipped | H100: Classic Cars | I100: 147 | J100: S10_4962 | K100: Handji Gifts& Co | L100: +65 224 1555 | M100: Village Close - 106 Linden Road Sandown | N100: Singapore | O100: 69045 | P100: Singapore | Q100: Victorino | R100: Wendy | S100: Large | T100: 616 | U100: =VLOOKUP(Auto_Sales_data___Copy[[#This Row],[CUSTOMER_NAME]],$AF$2:$AH$90,2,FALSE) -> 36 | V100: =VLOOKUP(Auto_Sales_data___Copy[[#This Row],[CUSTOMER_NAME]],$AF$2:$AH$90,3,FALSE) -> 115498.73 | W100: =6-MATCH(Auto_Sales_data___Copy[[#This Row],[DAYS_SINCE_LAST_ORDER]],Table2[R-Cutoff],1) -> 5 | X100: =MATCH(Auto_Sales_data___Copy[[#This Row],[Total_Orders_Per_Customer]],Table2[F-Cutoff],1) -> 4 | Y100: =MATCH(Auto_Sales_data___Copy[[#This Row],[Total_Sales_Per_Customer]],Table2[M-Cutoff],1) -> 4 | Z100: =Auto_Sales_data___Copy[[#This Row],[R-Score(1-5)]]&Auto_Sales_data___Copy[[#This Row],[F-Score(1-5)]]&Auto_Sales_data___Copy[[#This Row],[M-Score(1-5)]] -> 544 | AA100: {=_xlfn.IFS(OR(Auto_Sales_data___Copy[[#This Row],[R-Score(1-5)]]=5,Auto_Sales_data___Copy[[#This Row],[R-Score(1-5)]]=4)*AND(Auto_Sales_data___Copy[[#This Row],[F-Score(1-5)]]>=4,Auto_Sales_data___Copy[[#This Row],[M-Score(1-5)]]>=4),'Segments & Strategies'!$A$2,AND(Auto_Sales_data___Copy[[#This Row],[R-Score(1-5)]]=3,Auto_Sales_data___Copy[[#This Row],[F-Score(1-5)]]>=4,Auto_Sales_data___Copy[[#This Row],[M-Score(1-5)]]>=4),'Segments & Strategies'!$A$3,AND(Auto_Sales_data___Copy[[#This Row],[R-Score(1-5)]]>=4,Auto_Sales_data___Copy[[#This Row],[F-Score(1-5)]]=5,Auto_Sales_data___Copy[[#This Row],[M-Score(1-5)]]<=3),'Segments & Strategies'!$A$4, AND(Auto_Sales_data___Copy[[#This Row],[R-Score(1-5)]]=2,Auto_Sales_data___Copy[[#This Row],[F-Score(1-5)]]>=4,Auto_Sales_data___Copy[[#This Row],[M-Score(1-5)]]>=4),'Segments & Strategies'!$A$6,AND(Auto_Sales_data___Copy[[#This Row],[R-Score(1-5)]]=1,Auto_Sales_data___Copy[[#This Row],[F-Score(1-5)]]<=2,Auto_Sales_data___Copy[[#This Row],[M-Score(1-5)]]<=2),'Segments & Strategies'!$A$8,AND(Auto_Sales_data___Copy[[#This Row],[R-Score(1-5)]]<=3,Auto_Sales_data___Copy[[#This Row],[F-Score(1-5)]]<=3,Auto_Sales_data___Copy[[#This Row],[M-Score(1-5)]]<=2), 'Segments & Strategies'!$A$7, TRUE,'Segments & Strategies'!$A$5)} -> Champion | AB100: =VLOOKUP(Auto_Sales_data___Copy[[#This Row],[Segment Name]],Table3[],2,FALSE) -> VIP Recognitioon & Inclusivity
A101: 10223 | B101: 37 | C101: 107.18 | D101: 1 | E101: 3965.66 | F101: 43516 | G101: Shipped | H101: Motorcycles | I101: 95 | J101: S10_1678 | K101: Australian Collectors, Co. | L101: 03 9520 4555 | M101: 636 St Kilda Road | N101: Melbourne | O101: 3004 | P101: Australia | Q101: Ferguson | R101: Peter | S101: Medium | T101: 475 | U101: =VLOOKUP(Auto_Sales_data___Copy[[#This Row],[CUSTOMER_NAME]],$AF$2:$AH$90,2,FALSE) -> 55 | V101: =VLOOKUP(Auto_Sales_data___Copy[[#This Row],[CUSTOMER_NAME]],$AF$2:$AH$90,3,FALSE) -> 200995.41 | W101: =6-MATCH(Auto_Sales_data___Copy[[#This Row],[DAYS_SINCE_LAST_ORDER]],Table2[R-Cutoff],1) -> 5 | X101: =MATCH(Auto_Sales_data___Copy[[#This Row],[Total_Orders_Per_Customer]],Table2[F-Cutoff],1) -> 4 | Y101: =MATCH(Auto_Sales_data___Copy[[#This Row],[Total_Sales_Per_Customer]],Table2[M-Cutoff],1) -> 4 | Z101: =Auto_Sales_data___Copy[[#This Row],[R-Score(1-5)]]&Auto_Sales_data___Copy[[#This Row],[F-Score(1-5)]]&Auto_Sales_data___Copy[[#This Row],[M-Score(1-5)]] -> 544 | AA101: {=_xlfn.IFS(OR(Auto_Sales_data___Copy[[#This Row],[R-Score(1-5)]]=5,Auto_Sales_data___Copy[[#This Row],[R-Score(1-5)]]=4)*AND(Auto_Sales_data___Copy[[#This Row],[F-Score(1-5)]]>=4,Auto_Sales_data___Copy[[#This Row],[M-Score(1-5)]]>=4),'Segments & Strategies'!$A$2,AND(Auto_Sales_data___Copy[[#This Row],[R-Score(1-5)]]=3,Auto_Sales_data___Copy[[#This Row],[F-Score(1-5)]]>=4,Auto_Sales_data___Copy[[#This Row],[M-Score(1-5)]]>=4),'Segments & Strategies'!$A$3,AND(Auto_Sales_data___Copy[[#This Row],[R-Score(1-5)]]>=4,Auto_Sales_data___Copy[[#This Row],[F-Score(1-5)]]=5,Auto_Sales_data___Copy[[#This Row],[M-Score(1-5)]]<=3),'Segments & Strategies'!$A$4, AND(Auto_Sales_data___Copy[[#This Row],[R-Score(1-5)]]=2,Auto_Sales_data___Copy[[#This Row],[F-Score(1-5)]]>=4,Auto_Sales_data___Copy[[#This Row],[M-Score(1-5)]]>=4),'Segments & Strategies'!$A$6,AND(Auto_Sales_data___Copy[[#This Row],[R-Score(1-5)]]=1,Auto_Sales_data___Copy[[#This Row],[F-Score(1-5)]]<=2,Auto_Sales_data___Copy[[#This Row],[M-Score(1-5)]]<=2),'Segments & Strategies'!$A$8,AND(Auto_Sales_data___Copy[[#This Row],[R-Score(1-5)]]<=3,Auto_Sales_data___Copy[[#This Row],[F-Score(1-5)]]<=3,Auto_Sales_data___Copy[[#This Row],[M-Score(1-5)]]<=2), 'Segments & Strategies'!$A$7, TRUE,'Segments & Strategies'!$A$5)} -> Champion | AB101: =VLOOKUP(Auto_Sales_data___Copy[[#This Row],[Segment Name]],Table3[],2,FALSE) -> VIP Recognitioon & Inclusivity
A102: 10223 | B102: 47 | C102: 115.37 | D102: 4 | E102: 5422.39 | F102: 43516 | G102: Shipped | H102: Motorcycles | I102: 118 | J102: S10_2016 | K102: Australian Collectors, Co. | L102: 03 9520 4555 | M102: 636 St Kilda Road | N102: Melbourne | O102: 3004 | P102: Australia | Q102: Ferguson | R102: Peter | S102: Medium | T102: 525 | U102: =VLOOKUP(Auto_Sales_data___Copy[[#This Row],[CUSTOMER_NAME]],$AF$2:$AH$90,2,FALSE) -> 55 | V102: =VLOOKUP(Auto_Sales_data___Copy[[#This Row],[CUSTOMER_NAME]],$AF$2:$AH$90,3,FALSE) -> 200995.41 | W102: =6-MATCH(Auto_Sales_data___Copy[[#This Row],[DAYS_SINCE_LAST_ORDER]],Table2[R-Cutoff],1) -> 5 | X102: =MATCH(Auto_Sales_data___Copy[[#This Row],[Total_Orders_Per_Customer]],Table2[F-Cutoff],1) -> 4 | Y102: =MATCH(Auto_Sales_data___Copy[[#This Row],[Total_Sales_Per_Customer]],Table2[M-Cutoff],1) -> 4 | Z102: =Auto_Sales_data___Copy[[#This Row],[R-Score(1-5)]]&Auto_Sales_data___Copy[[#This Row],[F-Score(1-5)]]&Auto_Sales_data___Copy[[#This Row],[M-Score(1-5)]] -> 544 | AA102: {=_xlfn.IFS(OR(Auto_Sales_data___Copy[[#This Row],[R-Score(1-5)]]=5,Auto_Sales_data___Copy[[#This Row],[R-Score(1-5)]]=4)*AND(Auto_Sales_data___Copy[[#This Row],[F-Score(1-5)]]>=4,Auto_Sales_data___Copy[[#This Row],[M-Score(1-5)]]>=4),'Segments & Strategies'!$A$2,AND(Auto_Sales_data___Copy[[#This Row],[R-Score(1-5)]]=3,Auto_Sales_data___Copy[[#This Row],[F-Score(1-5)]]>=4,Auto_Sales_data___Copy[[#This Row],[M-Score(1-5)]]>=4),'Segments & Strategies'!$A$3,AND(Auto_Sales_data___Copy[[#This Row],[R-Score(1-5)]]>=4,Auto_Sales_data___Copy[[#This Row],[F-Score(1-5)]]=5,Auto_Sales_data___Copy[[#This Row],[M-Score(1-5)]]<=3),'Segments & Strategies'!$A$4, AND(Auto_Sales_data___Copy[[#This Row],[R-Score(1-5)]]=2,Auto_Sales_data___Copy[[#This Row],[F-Score(1-5)]]>=4,Auto_Sales_data___Copy[[#This Row],[M-Score(1-5)]]>=4),'Segments & Strategies'!$A$6,AND(Auto_Sales_data___Copy[[#This Row],[R-Score(1-5)]]=1,Auto_Sales_data___Copy[[#This Row],[F-Score(1-5)]]<=2,Auto_Sales_data___Copy[[#This Row],[M-Score(1-5)]]<=2),'Segments & Strategies'!$A$8,AND(Auto_Sales_data___Copy[[#This Row],[R-Score(1-5)]]<=3,Auto_Sales_data___Copy[[#This Row],[F-Score(1-5)]]<=3,Auto_Sales_data___Copy[[#This Row],[M-Score(1-5)]]<=2), 'Segments & Strategies'!$A$7, TRUE,'Segments & Strategies'!$A$5)} -> Champion | AB102: =VLOOKUP(Auto_Sales_data___Copy[[#This Row],[Segment Name]],Table3[],2,FALSE) -> VIP Recognitioon & Inclusivity
